Traceback (most recent call last):
  File "/Users/skojaku-admin/miniforge3/envs/advnetsci/lib/python3.11/site-packages/jupyter_cache/executors/utils.py", line 58, in single_nb_execution
    executenb(
  File "/Users/skojaku-admin/miniforge3/envs/advnetsci/lib/python3.11/site-packages/nbclient/client.py", line 1305, in execute
    return NotebookClient(nb=nb, resources=resources, km=km, **kwargs).execute()
           ^^^^^^^^^^^^^^^^^^^^^^^^^^^^^^^^^^^^^^^^^^^^^^^^^^^^^^^^^^^^^^^^^^^^^
  File "/Users/skojaku-admin/miniforge3/envs/advnetsci/lib/python3.11/site-packages/jupyter_core/utils/__init__.py", line 165, in wrapped
    return loop.run_until_complete(inner)
           ^^^^^^^^^^^^^^^^^^^^^^^^^^^^^^
  File "/Users/skojaku-admin/miniforge3/envs/advnetsci/lib/python3.11/asyncio/base_events.py", line 650, in run_until_complete
    return future.result()
           ^^^^^^^^^^^^^^^
  File "/Users/skojaku-admin/miniforge3/envs/advnetsci/lib/python3.11/contextlib.py", line 222, in __aexit__
    await self.gen.athrow(typ, value, traceback)
  File "/Users/skojaku-admin/miniforge3/envs/advnetsci/lib/python3.11/site-packages/nbclient/client.py", line 650, in async_setup_kernel
    yield
  File "/Users/skojaku-admin/miniforge3/envs/advnetsci/lib/python3.11/site-packages/nbclient/client.py", line 705, in async_execute
    await self.async_execute_cell(
  File "/Users/skojaku-admin/miniforge3/envs/advnetsci/lib/python3.11/site-packages/nbclient/client.py", line 1058, in async_execute_cell
    await self._check_raise_for_error(cell, cell_index, exec_reply)
  File "/Users/skojaku-admin/miniforge3/envs/advnetsci/lib/python3.11/site-packages/nbclient/client.py", line 914, in _check_raise_for_error
    raise CellExecutionError.from_cell_and_msg(cell, exec_reply_content)
nbclient.exceptions.CellExecutionError: An error occurred while executing the following cell:
------------------
import kagglehub

# Download latest version
path = kagglehub.dataset_download("quora/question-pairs-dataset")

print("Path to dataset files:", path)

------------------


[0;31m---------------------------------------------------------------------------[0m
[0;31mModuleNotFoundError[0m                       Traceback (most recent call last)
Cell [0;32mIn[7], line 1[0m
[0;32m----> 1[0m [38;5;28;01mimport[39;00m [38;5;21;01mkagglehub[39;00m
[1;32m      3[0m [38;5;66;03m# Download latest version[39;00m
[1;32m      4[0m path [38;5;241m=[39m kagglehub[38;5;241m.[39mdataset_download([38;5;124m"[39m[38;5;124mquora/question-pairs-dataset[39m[38;5;124m"[39m)

[0;31mModuleNotFoundError[0m: No module named 'kagglehub'

